<?xml version="1.0" encoding="utf-8"?>
<!-- This URDF was automatically created by SolidWorks to URDF Exporter! Originally created by Stephen Brawner (brawner@gmail.com) 
     Commit Version: 1.6.0-4-g7f85cfe  Build Version: 1.6.7995.38578
     For more information, please see http://wiki.ros.org/sw_urdf_exporter -->
<robot
  name="robot_arm_urdf">
  <link
    name="base_link">
    <inertial>
      <origin
        xyz="0.0032394 0.022567 -4.5383E-10"
        rpy="0 0 0" />
      <mass
        value="1.22787" />
      <inertia
        ixx="0.00011996"
        ixy="-1.0737E-06"
        ixz="-4.1525E-14"
        iyy="0.00020378"
        iyz="4.5573E-13"
        izz="0.000134" />
    </inertial>
    <visual>
      <origin
        xyz="0 0 0"
        rpy="0 0 0" />
      <geometry>
        <mesh
          filename="package://robot_arm_urdf/meshes/base_link.STL" />
      </geometry>
      <material
        name="">
        <color
          rgba="0.79216 0.81961 0.93333 1" />
      </material>
    </visual>
    <collision>
      <origin
        xyz="0 0 0"
        rpy="0 0 0" />
      <geometry>
        <mesh
          filename="package://robot_arm_urdf/meshes/base_link.STL" />
      </geometry>
    </collision>
  </link>
  <link
    name="rotating_Link">
    <inertial>
      <origin
        xyz="-0.0125350268571904 0.0233608533773388 7.50059833673825E-08"
        rpy="0 0 0" />
      <mass
        value="0.123597949087119" />
      <inertia
        ixx="8.32891212084354E-05"
        ixy="7.68878516719148E-06"
        ixz="2.77787381114411E-10"
        iyy="7.65400668372014E-05"
        iyz="-6.67658494977892E-11"
        izz="7.65101106376672E-05" />
    </inertial>
    <visual>
      <origin
        xyz="0 0 0"
        rpy="0 0 0" />
      <geometry>
        <mesh
          filename="package://robot_arm_urdf/meshes/rotating_Link.STL" />
      </geometry>
      <material
        name="">
        <color
          rgba="1 1 1 1" />
      </material>
    </visual>
    <collision>
      <origin
        xyz="0 0 0"
        rpy="0 0 0" />
      <geometry>
        <mesh
          filename="package://robot_arm_urdf/meshes/rotating_Link.STL" />
      </geometry>
    </collision>
  </link>
  <joint
    name="rotating_joint"
    type="revolute">
    <origin
      xyz="0 0.05 0"
      rpy="0 1.5708 0" />
    <parent
      link="base_link" />
    <child
      link="rotating_Link" />
    <axis
      xyz="0 0 0" />
    <limit
      lower="-1.57"
      upper="1.57"
      effort="0.1"
      velocity="0.2" />
  </joint>
  <link
    name="upperarm_Link">
    <inertial>
      <origin
        xyz="5.5511E-17 0.0079569 2.187E-16"
        rpy="0 0 0" />
      <mass
        value="0.12015" />
      <inertia
        ixx="2.3791E-05"
        ixy="2.846E-19"
        ixz="1.2636E-12"
        iyy="0.00039487"
        iyz="1.7927E-21"
        izz="0.00037741" />
    </inertial>
    <visual>
      <origin
        xyz="0 0 0"
        rpy="0 0 0" />
      <geometry>
        <mesh
          filename="package://robot_arm_urdf/meshes/upperarm_Link.STL" />
      </geometry>
      <material
        name="">
        <color
          rgba="1 1 1 1" />
      </material>
    </visual>
    <collision>
      <origin
        xyz="0 0 0"
        rpy="0 0 0" />
      <geometry>
        <mesh
          filename="package://robot_arm_urdf/meshes/upperarm_Link.STL" />
      </geometry>
    </collision>
  </link>
  <joint
    name="shoulder_joint"
    type="revolute">
    <origin
      xyz="0 0.11355 0"
      rpy="-3.1416 0 1.5708" />
    <parent
      link="rotating_Link" />
    <child
      link="upperarm_Link" />
    <axis
      xyz="0 0 0" />
    <limit
      lower="-1.57"
      upper="1.57"
      effort="0.1"
      velocity="0.2" />
  </joint>
  <link
    name="forearm_Link">
    <inertial>
      <origin
        xyz="0.050967 0.031378 -0.00031477"
        rpy="0 0 0" />
      <mass
        value="0.14762" />
      <inertia
        ixx="2.3289E-05"
        ixy="5.374E-06"
        ixz="6.3077E-06"
        iyy="0.0004054"
        iyz="-8.1891E-08"
        izz="0.00040129" />
    </inertial>
    <visual>
      <origin
        xyz="0 0 0"
        rpy="0 0 0" />
      <geometry>
        <mesh
          filename="package://robot_arm_urdf/meshes/forearm_Link.STL" />
      </geometry>
      <material
        name="">
        <color
          rgba="0.25098 0.25098 0.25098 1" />
      </material>
    </visual>
    <collision>
      <origin
        xyz="0 0 0"
        rpy="0 0 0" />
      <geometry>
        <mesh
          filename="package://robot_arm_urdf/meshes/forearm_Link.STL" />
      </geometry>
    </collision>
  </link>
  <joint
    name="arms_joint"
    type="revolute">
    <origin
      xyz="0.07 -0.0474 -0.01025"
      rpy="0 1.5708 0" />
    <parent
      link="upperarm_Link" />
    <child
      link="forearm_Link" />
    <axis
      xyz="0 0 0" />
    <limit
      lower="-1.57"
      upper="1.57"
      effort="0.1"
      velocity="0.2" />
  </joint>
  <link
    name="leftside_Link">
    <inertial>
      <origin
        xyz="0.0155 0.00825 5.175E-09"
        rpy="0 0 0" />
      <mass
        value="0.0015975" />
      <inertia
        ixx="7.265E-09"
        ixy="9.9301E-23"
        ixz="-2.3118E-14"
        iyy="2.0885E-07"
        iyz="1.8619E-25"
        izz="2.0584E-07" />
    </inertial>
    <visual>
      <origin
        xyz="0 0 0"
        rpy="0 0 0" />
      <geometry>
        <mesh
          filename="package://robot_arm_urdf/meshes/leftside_Link.STL" />
      </geometry>
      <material
        name="">
        <color
          rgba="0.79216 0.81961 0.93333 1" />
      </material>
    </visual>
    <collision>
      <origin
        xyz="0 0 0"
        rpy="0 0 0" />
      <geometry>
        <mesh
          filename="package://robot_arm_urdf/meshes/leftside_Link.STL" />
      </geometry>
    </collision>
  </link>
  <joint
    name="leftlink_joint"
    type="revolute">
    <origin
      xyz="0.17805 0.04015 0.0012817"
      rpy="-1.5708 0 0.1129" />
    <parent
      link="forearm_Link" />
    <child
      link="leftside_Link" />
    <axis
      xyz="0 0 0" />
    <limit
      lower="0"
      upper="1.57"
      effort="0"
      velocity="0" />
    <mimic
      joint="rightlink_joint"
      multiplier="1"
      offset="0" />
  </joint>
  <link
    name="rightside_link">
    <inertial>
      <origin
        xyz="0.0155 -0.00425 -4.2952E-15"
        rpy="0 0 0" />
      <mass
        value="0.0015975" />
      <inertia
        ixx="7.265E-09"
        ixy="2.2935E-22"
        ixz="1.8793E-23"
        iyy="2.0885E-07"
        iyz="-2.0142E-24"
        izz="2.0584E-07" />
    </inertial>
    <visual>
      <origin
        xyz="0 0 0"
        rpy="0 0 0" />
      <geometry>
        <mesh
          filename="package://robot_arm_urdf/meshes/rightside_link.STL" />
      </geometry>
      <material
        name="">
        <color
          rgba="0.79216 0.81961 0.93333 1" />
      </material>
    </visual>
    <collision>
      <origin
        xyz="0 0 0"
        rpy="0 0 0" />
      <geometry>
        <mesh
          filename="package://robot_arm_urdf/meshes/rightside_link.STL" />
      </geometry>
    </collision>
  </link>
  <joint
    name="rightlink_joint"
    type="revolute">
    <origin
      xyz="0.17805 0.03015 -0.011218"
      rpy="-1.5708 0 -0.017804" />
    <parent
      link="forearm_Link" />
    <child
      link="rightside_link" />
    <axis
      xyz="0 0 0" />
    <limit
      lower="0"
      upper="0"
      effort="0"
      velocity="0" />
  </joint>
  <link
    name="rightgear_Link">
    <inertial>
      <origin
        xyz="-0.017371 0.0017437 0.00040231"
        rpy="0 0 0" />
      <mass
        value="0.0028245" />
      <inertia
        ixx="1.025E-07"
        ixy="-1.2936E-08"
        ixz="5.8922E-08"
        iyy="5.4141E-07"
        iyz="2.1041E-09"
        izz="4.4993E-07" />
    </inertial>
    <visual>
      <origin
        xyz="0 0 0"
        rpy="0 0 0" />
      <geometry>
        <mesh
          filename="package://robot_arm_urdf/meshes/rightgear_Link.STL" />
      </geometry>
      <material
        name="">
        <color
          rgba="0.79216 0.81961 0.93333 1" />
      </material>
    </visual>
    <collision>
      <origin
        xyz="0 0 0"
        rpy="0 0 0" />
      <geometry>
        <mesh
          filename="package://robot_arm_urdf/meshes/rightgear_Link.STL" />
      </geometry>
    </collision>
  </link>
  <joint
    name="rightgear_joint"
    type="revolute">
    <origin
      xyz="0.14835 0.020267 -0.013568"
      rpy="-1.5708 0 -3.0441" />
    <parent
      link="forearm_Link" />
    <child
      link="rightgear_Link" />
    <axis
      xyz="0 0 0" />
    <limit
      lower="0"
      upper="1.57"
      effort="0.1"
      velocity="0.5" />
  </joint>
  <link
    name="rightfinger_Link">
    <inertial>
      <origin
        xyz="0.00425 0.0095132 -0.03189"
        rpy="0 0 0" />
      <mass
        value="0.0053975" />
      <inertia
        ixx="1.7139E-06"
        ixy="1.2438E-11"
        ixz="6.4938E-12"
        iyy="1.5958E-06"
        iyz="3.7341E-07"
        izz="1.8308E-07" />
    </inertial>
    <visual>
      <origin
        xyz="0 0 0"
        rpy="0 0 0" />
      <geometry>
        <mesh
          filename="package://robot_arm_urdf/meshes/rightfinger_Link.STL" />
      </geometry>
      <material
        name="">
        <color
          rgba="0.79216 0.81961 0.93333 1" />
      </material>
    </visual>
    <collision>
      <origin
        xyz="0 0 0"
        rpy="0 0 0" />
      <geometry>
        <mesh
          filename="package://robot_arm_urdf/meshes/rightfinger_Link.STL" />
      </geometry>
    </collision>
  </link>
  <joint
    name="rightfinger_joint"
    type="revolute">
    <origin
      xyz="-0.034203 -0.01085 0.00098559"
      rpy="1.2279 0 1.5708" />
    <parent
      link="rightgear_Link" />
    <child
      link="rightfinger_Link" />
    <axis
      xyz="0 0 0" />
    <limit
      lower="0"
      upper="1.57"
      effort="0.1"
      velocity="0.2" />
  </joint>
  <link
    name="leftgear_Link">
    <inertial>
      <origin
        xyz="-0.0045276 0.001 -0.00060197"
        rpy="0 0 0" />
      <mass
        value="0.0039624" />
      <inertia
        ixx="1.4167E-07"
        ixy="-6.8068E-22"
        ixz="-1.3886E-08"
        iyy="6.7086E-07"
        iyz="1.1273E-23"
        izz="5.5296E-07" />
    </inertial>
    <visual>
      <origin
        xyz="0 0 0"
        rpy="0 0 0" />
      <geometry>
        <mesh
          filename="package://robot_arm_urdf/meshes/leftgear_Link.STL" />
      </geometry>
      <material
        name="">
        <color
          rgba="0.79216 0.81961 0.93333 1" />
      </material>
    </visual>
    <collision>
      <origin
        xyz="0 0 0"
        rpy="0 0 0" />
      <geometry>
        <mesh
          filename="package://robot_arm_urdf/meshes/leftgear_Link.STL" />
      </geometry>
    </collision>
  </link>
  <joint
    name="leftgear_joint"
    type="revolute">
    <origin
      xyz="0.16759 0.049104 -0.013218"
      rpy="-1.5708 0 0.09458" />
    <parent
      link="forearm_Link" />
    <child
      link="leftgear_Link" />
    <axis
      xyz="0 0 0" />
    <limit
      lower="0"
      upper="1.57"
      effort="0.1"
      velocity="0.2" />
    <mimic
      joint="rightgear_joint"
      multiplier="1"
      offset="0" />
  </joint>
  <link
    name="leftfinger_Link">
    <inertial>
      <origin
        xyz="0.00425 0.0095131 -0.03189"
        rpy="0 0 0" />
      <mass
        value="0.0053975" />
      <inertia
        ixx="1.7139E-06"
        ixy="1.244E-11"
        ixz="6.4983E-12"
        iyy="1.5958E-06"
        iyz="3.7341E-07"
        izz="1.8308E-07" />
    </inertial>
    <visual>
      <origin
        xyz="0 0 0"
        rpy="0 0 0" />
      <geometry>
        <mesh
          filename="package://robot_arm_urdf/meshes/leftfinger_Link.STL" />
      </geometry>
      <material
        name="">
        <color
          rgba="0.79216 0.81961 0.93333 1" />
      </material>
    </visual>
    <collision>
      <origin
        xyz="0 0 0"
        rpy="0 0 0" />
      <geometry>
        <mesh
          filename="package://robot_arm_urdf/meshes/leftfinger_Link.STL" />
      </geometry>
    </collision>
  </link>
  <joint
    name="leftfinger_joint"
    type="revolute">
    <origin
      xyz="0.013995 -0.002 -0.0024061"
      rpy="1.1326 0 -1.5708" />
    <parent
      link="leftgear_Link" />
    <child
      link="leftfinger_Link" />
    <axis
      xyz="0 0 0" />
    <limit
      lower="0"
      upper="1.57"
      effort="0.1"
      velocity="0.2" />
    <mimic
      joint="rightfinger_joint"
      multiplier="1"
      offset="0" />
  </joint>
</robot>